Workbook

Sheet Raw_Data
A1: CAMPAIGN ID | B1: CHANNEL | C1: CAMPAIGN NAME | D1: SPEND | E1: CLICKS | F1: CONVERSIONS | G1: REVENUE | H1: CTR | I1: ROAS | J1: MONTH
A2: CMP0002 | B2: Facebook Ads | C2: New Launch | D2: 12009.39 | E2: 963 | F2: 104 | G2: 1362.8 | I2: 0.11 | J2: 2024-05
A3: CMP0003 | B3: Facebook Ads | C3: Flash Sale | D3: 14303.48 | E3: 644 | F3: 5 | G3: 22080.11 | H3: 2.66 | I3: 1.54 | J3: 2024-07
A4: CMP0006 | B4: Email | C4: Summer Sale | D4: 7627.32 | E4: 2148 | F4: 28 | G4: 6803.67 | H4: 1.34 | I4: 0.89 | J4: 2024-01
A5: CMP0007 | B5: Instagram | C5: Brand Awareness | D5: 13980.7 | E5: 700 | F5: 95 | G5: 1467.89 | H5: 1.5 | I5: 0.1 | J5: 2024-08
A6: CMP0008 | B6: Email | C6: New Launch | D6: 14440.73 | E6: 1429 | F6: 62 | G6: 2773.41 | H6: 1.44 | I6: 0.19 | J6: 2024-06
A7: CMP0009 | B7: Email | C7: Summer Sale | D7: 12636.48 | E7: 1066 | F7: 43 | G7: 34815.43 | H7: 10.54 | I7: 2.76 | J7: 2024-07
A8: CMP0013 | B8: Email | C8: New Launch | D8: 1542.4 | E8: 1162 | F8: 101 | G8: 8784.32 | I8: 5.7 | J8: 2024-07
A9: CMP0014 | B9: Google Ads | C9: Flash Sale | D9: 11290.88 | E9: 2483 | F9: 2 | G9: 34578.52 | H9: 1.26 | I9: 3.06 | J9: 2024-02
A10: CMP0015 | B10: Google Ads | C10: Diwali Offer | D10: 14478.03 | E10: 181 | F10: 75 | G10: 32122.94 | H10: 0.43 | I10: 2.22 | J10: 2024-05
A11: CMP0019 | B11: Email | C11: New Launch | D11: 6284.62 | E11: 943 | F11: 122 | G11: 14921.11 | H11: 0.55 | I11: 2.37 | J11: 2024-07
A12: CMP0020 | B12: Instagram | C12: New Launch | D12: 7477.4 | E12: 1263 | F12: 1 | G12: 8081.45 | I12: 1.08 | J12: 2024-02
A13: CMP0023 | B13: Email | C13: New Launch | D13: 14140.61 | E13: 1799 | F13: 44 | G13: 24868.44 | H13: 1.02 | I13: 1.76 | J13: 2024-06
A14: CMP0026 | B14: Google Ads | C14: Retargeting | D14: 6343.08 | E14: 932 | F14: 4 | G14: 2920.48 | I14: 0.46 | J14: 2024-01
A15: CMP0028 | B15: Facebook Ads | C15: Summer Sale | D15: 10188.62 | E15: 412 | F15: 90 | G15: 1485.91 | H15: 0.81 | I15: 0.15 | J15: 2024-12
A16: CMP0029 | B16: Email | C16: New Launch | D16: 970.37 | E16: 1478 | F16: 49 | G16: 20983.2 | H16: 1.37 | I16: 21.62 | J16: 2024-06
A17: CMP0030 | B17: Google Ads | C17: Brand Awareness | D17: 1086.93 | E17: 2191 | F17: 94 | G17: 6480.42 | H17: 1.29 | I17: 5.96 | J17: 2024-07
A18: CMP0032 | B18: Instagram | C18: Summer Sale | D18: 13741.49 | E18: 1096 | F18: 41 | G18: 38979.68 | H18: 0.55 | I18: 2.84 | J18: 2024-08
A19: CMP0034 | B19: Facebook Ads | C19: Retargeting | D19: 14341.98 | E19: 2735 | F19: 136 | G19: 35803 | H19: 1.4 | I19: 2.5 | J19: 2024-05
A20: CMP0035 | B20: Google Ads | C20: Flash Sale | D20: 6651.76 | E20: 2036 | F20: 47 | G20: 15121.6 | H20: 1.19 | I20: 2.27 | J20: 2024-02
A21: CMP0036 | B21: LinkedIn Ads | C21: Retargeting | D21: 3484.27 | E21: 1386 | F21: 0 | G21: 15074.92 | H21: 1.73 | I21: 4.33 | J21: 2024-03
A22: CMP0037 | B22: Instagram | C22: Brand Awareness | D22: 12570.11 | E22: 2000 | F22: 123 | G22: 0 | H22: 1.03 | I22: 0 | J22: 2024-01
A23: CMP0038 | B23: Instagram | C23: Retargeting | D23: 5637.5 | E23: 1844 | F23: 65 | G23: 14996.61 | H23: 1.01 | I23: 2.66 | J23: 2024-02
A24: CMP0039 | B24: Facebook Ads | C24: New Launch | D24: 9133.12 | E24: 326 | F24: 37 | G24: 37407.61 | H24: 0.49 | I24: 4.1 | J24: 2024-07
A25: CMP0040 | B25: Google Ads | C25: Brand Awareness | D25: 3500.97 | E25: 2930 | F25: 0 | G25: 20903.59 | H25: 31.07 | I25: 5.97 | J25: 2024-06
A26: CMP0044 | B26: Instagram | C26: Diwali Offer | D26: 3623.21 | E26: 774 | F26: 39 | G26: 4470.25 | H26: 20.86 | I26: 1.23 | J26: 2024-03
... A37: CMP0059 | B37: Google Ads | C37: Summer Sale | D37: 3020.26 | E37: 1698 | F37: 98 | G37: 34195.67 | H37: 2.94 | I37: 11.32 | J37: 2024-07
A38: CMP0060 | B38: Google Ads | C38: Diwali Offer | D38: 5157.34 | E38: 1784 | F38: 21 | G38: 35993.19 | I38: 6.98 | J38: 2024-07
A39: CMP0064 | B39: Google Ads | C39: Retargeting | D39: 9979.42 | E39: 1453 | F39: 136 | G39: 36456.75 | H39: 0.74 | I39: 3.65 | J39: 2024-08
A40: CMP0065 | B40: Email | C40: Diwali Offer | D40: 7353.47 | E40: 999 | F40: 49 | G40: 12615.19 | H40: 0.8 | I40: 1.72 | J40: 2024-08
A41: CMP0066 | B41: LinkedIn Ads | C41: Retargeting | D41: 11411.55 | E41: 1091 | F41: 0 | G41: 0 | I41: 0 | J41: 2024-07
A42: CMP0067 | B42: Email | C42: Retargeting | D42: 9152.81 | E42: 2066 | F42: 29 | G42: 22526.36 | H42: 1.29 | I42: 2.46 | J42: 2024-02
A43: CMP0068 | B43: Facebook Ads | C43: Brand Awareness | D43: 11658.43 | E43: 2619 | F43: 101 | G43: 27696.29 | H43: 2.3 | I43: 2.38 | J43: 2024-05
A44: CMP0070 | B44: Instagram | C44: Diwali Offer | D44: 5924.38 | E44: 1762 | F44: 59 | G44: 4131.8 | H44: 2.51 | I44: 0.7 | J44: 2024-01
A45: CMP0075 | B45: Facebook Ads | C45: Retargeting | D45: 6277.15 | E45: 1972 | F45: 105 | G45: 36359.67 | H45: 1.21 | I45: 5.79 | J45: 2024-01
A46: CMP0076 | B46: Instagram | C46: New Launch | D46: 7347.93 | E46: 2301 | F46: 0 | G46: 35617.27 | H46: 1.18 | I46: 4.85 | J46: 2024-08
A47: CMP0077 | B47: Instagram | C47: Diwali Offer | D47: 12695.49 | E47: 1169 | F47: 0 | G47: 2788.51 | I47: 0.22 | J47: 2024-07
A48: CMP0080 | B48: Google Ads | C48: Retargeting | D48: 12049.55 | E48: 854 | F48: 13 | G48: 15892.29 | H48: 0.5 | I48: 1.32 | J48: 2024-07
A49: CMP0084 | B49: Facebook Ads | C49: Diwali Offer | D49: 7918.4 | E49: 2535 | F49: 66 | G49: 25527.92 | I49: 3.22 | J49: 2024-02
A50: CMP0088 | B50: Instagram | C50: Diwali Offer | D50: 6093.66 | E50: 2468 | F50: 8 | G50: 10666.69 | H50: 2.73 | I50: 1.75 | J50: 2024-09
...

Sheet Dashboard
B2: Marketing Campaign ROI Dashboard
B6: Total Spend | D6: Total Revenue | F6: Overall ROAS | H6: Avg CTR
B7: =SUM(Raw_Data!$D$2:$D$210) -> 1676890 | D7: =SUM(Raw_Data!$G$2:$G$210) -> 3580134.8 | F7: =D7/B7 -> 2.1349849 | H7: =AVERAGE(Raw_Data!$H$2:$H$210) -> 3.8753646
B10: ROAS by Channel | G10: Monthly Spend vs Revenue
B11: Channel | C11: Spend | D11: Revenue | E11: ROAS | G11: Month | H11: Spend | I11: Revenue
B12: Email | C12: =SUMIF(Raw_Data!$B$2:$B$210,B12,Raw_Data!$D$2:$D$210) -> 336100.39 | D12: =SUMIF(Raw_Data!$B$2:$B$210,B12,Raw_Data!$G$2:$G$210) -> 781775.22 | E12: =IFERROR(D12/C12,0) -> 2.326017 | G12: 2024-01 | H12: =SUMIF(Raw_Data!$J$2:$J$210,G12,Raw_Data!$D$2:$D$210) -> 256866.67 | I12: =SUMIF(Raw_Data!$J$2:$J$210,G12,Raw_Data!$G$2:$G$210) -> 465595.95
B13: Facebook Ads | C13: =SUMIF(Raw_Data!$B$2:$B$210,B13,Raw_Data!$D$2:$D$210) -> 347472.76 | D13: =SUMIF(Raw_Data!$B$2:$B$210,B13,Raw_Data!$G$2:$G$210) -> 848930.37 | E13: =IFERROR(D13/C13,0) -> 2.4431566 | G13: 2024-02 | H13: =SUMIF(Raw_Data!$J$2:$J$210,G13,Raw_Data!$D$2:$D$210) -> 171019.39 | I13: =SUMIF(Raw_Data!$J$2:$J$210,G13,Raw_Data!$G$2:$G$210) -> 470105.93
B14: Google Ads | C14: =SUMIF(Raw_Data!$B$2:$B$210,B14,Raw_Data!$D$2:$D$210) -> 389163.38 | D14: =SUMIF(Raw_Data!$B$2:$B$210,B14,Raw_Data!$G$2:$G$210) -> 956528.16 | E14: =IFERROR(D14/C14,0) -> 2.457909 | G14: 2024-03 | H14: =SUMIF(Raw_Data!$J$2:$J$210,G14,Raw_Data!$D$2:$D$210) -> 145543.19 | I14: =SUMIF(Raw_Data!$J$2:$J$210,G14,Raw_Data!$G$2:$G$210) -> 293772.28
B15: Instagram | C15: =SUMIF(Raw_Data!$B$2:$B$210,B15,Raw_Data!$D$2:$D$210) -> 475593.73 | D15: =SUMIF(Raw_Data!$B$2:$B$210,B15,Raw_Data!$G$2:$G$210) -> 815492.34 | E15: =IFERROR(D15/C15,0) -> 1.7146827 | G15: 2024-04 | H15: =SUMIF(Raw_Data!$J$2:$J$210,G15,Raw_Data!$D$2:$D$210) -> 134435.16 | I15: =SUMIF(Raw_Data!$J$2:$J$210,G15,Raw_Data!$G$2:$G$210) -> 308222.17
B16: LinkedIn Ads | C16: =SUMIF(Raw_Data!$B$2:$B$210,B16,Raw_Data!$D$2:$D$210) -> 128559.7 | D16: =SUMIF(Raw_Data!$B$2:$B$210,B16,Raw_Data!$G$2:$G$210) -> 177408.73 | E16: =IFERROR(D16/C16,0) -> 1.3799716 | G16: 2024-05 | H16: =SUMIF(Raw_Data!$J$2:$J$210,G16,Raw_Data!$D$2:$D$210) -> 200653.59 | I16: =SUMIF(Raw_Data!$J$2:$J$210,G16,Raw_Data!$G$2:$G$210) -> 365640.5
G17: 2024-06 | H17: =SUMIF(Raw_Data!$J$2:$J$210,G17,Raw_Data!$D$2:$D$210) -> 203588.09 | I17: =SUMIF(Raw_Data!$J$2:$J$210,G17,Raw_Data!$G$2:$G$210) -> 502077.29
G18: 2024-07 | H18: =SUMIF(Raw_Data!$J$2:$J$210,G18,Raw_Data!$D$2:$D$210) -> 254316.38 | I18: =SUMIF(Raw_Data!$J$2:$J$210,G18,Raw_Data!$G$2:$G$210) -> 493769.7
G19: 2024-08 | H19: =SUMIF(Raw_Data!$J$2:$J$210,G19,Raw_Data!$D$2:$D$210) -> 217678.85 | I19: =SUMIF(Raw_Data!$J$2:$J$210,G19,Raw_Data!$G$2:$G$210) -> 520103.89
G20: 2024-09 | H20: =SUMIF(Raw_Data!$J$2:$J$210,G20,Raw_Data!$D$2:$D$210) -> 40798.71 | I20: =SUMIF(Raw_Data!$J$2:$J$210,G20,Raw_Data!$G$2:$G$210) -> 91439.67
G21: 2024-10 | H21: =SUMIF(Raw_Data!$J$2:$J$210,G21,Raw_Data!$D$2:$D$210) -> 9150.78 | I21: =SUMIF(Raw_Data!$J$2:$J$210,G21,Raw_Data!$G$2:$G$210) -> 573.9
G22: 2024-11 | H22: =SUMIF(Raw_Data!$J$2:$J$210,G22,Raw_Data!$D$2:$D$210) -> 32650.53 | I22: =SUMIF(Raw_Data!$J$2:$J$210,G22,Raw_Data!$G$2:$G$210) -> 67347.63
G23: 2024-12 | H23: =SUMIF(Raw_Data!$J$2:$J$210,G23,Raw_Data!$D$2:$D$210) -> 10188.62 | I23: =SUMIF(Raw_Data!$J$2:$J$210,G23,Raw_Data!$G$2:$G$210) -> 1485.91
